Workbook
Name Slicer_Product_name: #N/A
Name Slicer_Store_ID: #N/A

Sheet Customer_Dim
A1: Customer_ID | B1: Name | C1: Age | D1: Gender | E1: City | F1: State | G1: Country | H1: Loyalty_Level
A2: CUST1000 | B2: Sheena Bonilla | C2: 55 | D2: Male | E2: Donaldton | F2: North Carolina | G2: USA | H2: NO DATA
A3: CUST1001 | B3: Eugene Nelson | C3: 26 | D3: Female | E3: Phillipsmouth | F3: North Dakota | G3: USA | H3: Platinum
A4: CUST1002 | B4: Dr. Benjamin Price | C4: 29 | D4: Female | E4: Kylebury | F4: Alabama | G4: USA | H4: Platinum
A5: CUST1003 | B5: Jeremy Harris | C5: 59 | D5: Female | E5: Thomastown | F5: Ohio | G5: USA | H5: Bronze
A6: CUST1004 | B6: Caroline Collins | C6: 64 | D6: Female | E6: Nicholasshire | F6: California | G6: USA | H6: Silver
A7: CUST1005 | B7: Christine Vaughn | C7: 24 | D7: Male | E7: East Amandamouth | F7: Oregon | G7: USA | H7: Bronze
A8: CUST1006 | B8: Amber Jackson | C8: 29 | D8: Female | E8: Deborahborough | F8: South Dakota | G8: USA | H8: Platinum
A9: CUST1007 | B9: Daniel Boyd | C9: 29 | D9: Female | E9: West Pamelafurt | F9: West Virginia | G9: USA | H9: Bronze
A10: CUST1008 | B10: Melissa Howard | C10: 53 | D10: Female | E10: Maynardton | F10: New Hampshire | G10: USA | H10: Gold
A11: CUST1009 | B11: Ms. Maria Leach | C11: 64 | D11: Male | E11: Melissashire | F11: Pennsylvania | G11: USA | H11: Platinum
A12: CUST1010 | B12: Dominic Page | C12: 53 | D12: Male | E12: Port Michaelburgh | F12: Pennsylvania | G12: USA | H12: Bronze
A13: CUST1011 | B13: Brian Lopez | C13: 28 | D13: Female | E13: East Krista | F13: New York | G13: USA | H13: Gold
... A501: CUST1499 | B501: Philip Pennington | C501: 27 | D501: Female | E501: East Valerieview | F501: Oregon | G501: USA | H501: Platinum

Sheet Product_Dim
A1: Product_ID | B1: Product_Name | C1: Category | D1: Sub_Category | E1: Brand | F1: Cost Imputed | G1: Stock
A2: PROD0 | B2: Brother Laser Printer | C2: Electronics | D2: Computer | E2: Hunt Inc | F2: 112.42 | G2: 416
A3: PROD1 | B3: Men's Graphic T-Shirt | C3: Clothing | D3: Tops | E3: Terry-Moore | F3: 342.56 | G3: 181
A4: PROD2 | B4: Women's Casual Hoodie | C4: Clothing | D4: Outerwear | E4: Sims Inc | F4: 296.82667 | G4: 352
A5: PROD3 | B5: Men's Running Jacket | C5: Clothing | D5: Outerwear | E5: Pineda Ltd | F5: 364.67 | G5: 452
A6: PROD4 | B6: Women's Yoga Pants | C6: Clothing | D6: Bottoms | E6: Gonzales-Davis | F6: 306.46 | G6: 487
A7: PROD5 | B7: Men's Leather Belt | C7: Clothing | D7: Accessories | E7: Baldwin, Garza and Gonzalez | F7: 261 | G7: 59
A8: PROD6 | B8: Herbal Face Moisturizer | C8: Beauty | D8: Skincare | E8: Davidson PLC | F8: 312.8 | G8: 350
A9: PROD7 | B9: LED Table Lamp | C9: Home | D9: Lighting | E9: Harrell LLC | F9: 218.86 | G9: 170
A10: PROD8 | B10: Wireless Bluetooth Earbuds | C10: Electronics | D10: Audio | E10: Perez-Johnston | F10: 439.07 | G10: 142
A11: PROD9 | B11: Adjustable Dumbbell Set | C11: Sports | D11: Fitness | E11: Hill PLC | F11: 495.72 | G11: 323
A12: PROD10 | B12: Ceramic Kitchen Bowl Set | C12: Home | D12: Kitchen | E12: Hamilton Group | F12: 298.86 | G12: 308
A13: PROD11 | B13: HD Smart TV Stick | C13: Electronics | D13: Accessories | E13: Gibson, Hobbs and Weaver | F13: 449.4
A14: PROD12 | B14: Hair Strengthening Shampoo | C14: Beauty | D14: Haircare | E14: Rice LLC | F14: 115.82 | G14: 460
A15: PROD13 | B15: USB-C Fast Charger | C15: Electronics | D15: Accessories | E15: Dawson-Perkins | F15: 242.23 | G15: 453
A16: PROD14 | B16: Decorative Wall Mirror | C16: Home | D16: Decor | E16: Luna, Anderson and Bowman | F16: 48.01 | G16: 439
A17: PROD15 | B17: 4K Home Projector | C17: Electronics | D17: Appliances | E17: Thomas LLC | F17: 465.34 | G17: 301
A18: PROD16 | B18: Beard Grooming Kit | C18: Beauty | D18: Grooming | E18: Erickson-Green | F18: 337.42 | G18: 256
A19: PROD17 | B19: Soccer Training Cone Set | C19: Sports | D19: Accessories | E19: Ford, Murphy and Wilson | F19: 144.53 | G19: 367
A20: PROD18 | B20: Women's Denim Jeans | C20: Clothing | D20: Bottoms | E20: Guerra-Hendrix | F20: 303.74667 | G20: 343
A21: PROD19 | B21: Knee Support Brace | C21: Sports | D21: Equipment | E21: May-Reese | F21: 21.34 | G21: 65
A22: PROD20 | B22: Outdoor Sports Water Bottle | C22: Sports | D22: Accessories | E22: Soto-Ellis | F22: 131.51
A23: PROD21 | B23: Multi-Purpose Storage Box | C23: Home | D23: Storage | E23: Gardner-Montes | F23: 123.46 | G23: 76
A24: PROD22 | B24: Carbon Fiber Tennis Racket | C24: Sports | D24: Equipment | E24: Flores, Pineda and Rodriguez | F24: 484.62 | G24: 432
A25: PROD23 | B25: Men's Formal Shirt | C25: Clothing | D25: Tops | E25: Moon, Mora and Santos | F25: 282.995 | G25: 360
A26: PROD24 | B26: Foldable Camping Chair | C26: Sports | D26: Outdoor | E26: Cook Ltd | F26: 166.06 | G26: 340
A27: PROD25 | B27: Women's Scarf Set | C27: Clothing | D27: Accessories | E27: Brown and Sons | F27: 174.02 | G27: 268
A28: PROD26 | B28: Wireless Bluetooth Speaker | C28: Electronics | D28: Audio | E28: Reed-Schmidt | F28: 322.41 | G28: 213
A29: PROD27 | B29: Decorative Floor Vase | C29: Home | D29: Decor | E29: Khan, Jones and Paul | F29: 219.12333 | G29: 378
A30: PROD28 | B30: Sports Stopwatch Timer | C30: Sports | D30: Accessories | E30: Burns-Hansen | F30: 38.76 | G30: 137
A31: PROD29 | B31: Fabric Sofa Throw Blanket | C31: Home | D31: Decor | E31: Hoffman Group | F31: 218.48 | G31: 276
A32: PROD30 | B32: Stainless Steel Cutlery Set | C32: Home | D32: Kitchen | E32: Stevens, Fernandez and Martin | F32: 19.52 | G32: 57
A33: PROD31 | B33: Basketball | C33: Sports | D33: Team Sports | E33: Nolan-Snow | F33: 204.39 | G33: 281
A34: PROD32 | B34: Vitamin C Face Serum | C34: Beauty | D34: Skincare | E34: Griffin Ltd | F34: 283.83 | G34: 244
... A56: PROD54 | B56: Sports Stopwatch Pro | C56: Sports | D56: Accessories | E56: Thompson-French | F56: 434.84 | G56: 185
A57: PROD55 | B57: Ceramic Plant Pot | C57: Home | D57: Decor | E57: Hatfield, Baird and Torres | F57: 81.75
A58: PROD56 | B58: Premium Blanket Throw | C58: Home | D58: Decor | E58: Hernandez, Kennedy and Porter | F58: 461.47 | G58: 190
A59: PROD57 | B59: Foam Roller | C59: Sports | D59: Fitness | E59: Atkinson, Camacho and Oliver | F59: 30.62 | G59: 138
A60: PROD58 | B60: Womens Cotton Scarf | C60: Clothing | D60: Accessories | E60: Shepherd-Gould | F60: 113.83 | G60: 485
A61: PROD59 | B61: Men's Hair Styling Gel | C61: Beauty | D61: Haircare | E61: Cline-Mccarthy | F61: 17.31 | G61: 399
...

Sheet Store_Dim
A1: Store_ID | B1: Store_Name | C1: Region | D1: City | E1: Store_Type
A2: STORE0 | B2: Rivera-Warner | C2: East | D2: Washingtonfurt | E2: Flagship
A3: STORE1 | B3: Martinez, Adkins and Johnson | C3: North | D3: Danielmouth | E3: Flagship
A4: STORE2 | B4: Black-Horn | C4: South | D4: North Nancyview | E4: Outlet
A5: STORE3 | B5: Johnson-Wright | C5: North | D5: Hoodberg | E5: Outlet
A6: STORE4 | B6: Alexander Group | C6: South | D6: Port Sharon | E6: Online
A7: STORE5 | B7: Gray Ltd | C7: North | D7: New Michaelchester | E7: Outlet
A8: STORE6 | B8: Benson-Elliott | C8: East | D8: Port Josephberg | E8: Online
A9: STORE7 | B9: Martinez-Mullins | C9: South | D9: Williamsfurt | E9: Online
A10: STORE8 | B10: Bean, Jones and Park | C10: West | D10: Thompsonborough | E10: Online
A11: STORE9 | B11: Moore, Padilla and Butler | C11: South | D11: East Johnstad | E11: Flagship
A12: STORE10 | B12: Hill, Wagner and Ballard | C12: East | D12: East Davidville | E12: Online
... A21: STORE19 | B21: Mann-Austin | C21: East | D21: Vasquezborough | E21: Online

Sheet Sales_Fact
A1: Sales_ID | B1: Order_Date | C1: Customer_ID | D1: Product_ID | E1: Store_ID | F1: Quantity | G1: Unit_Price | H1: Discount | I1: Payment_Type | J1: Total_Amount Imputed | K1: Quantity Imputed | L1: Unit_Price imputed | M1: Discount Imputed | N1: Total_Amount Imputed
A2: SALE261 | B2: 45742 | C2: CUST1333 | D2: PROD0 | E2: STORE8 | F2: 4 | G2: 849.21 | H2: 0.07 | I2: Credit Card | J2: 3159.0612 | K2: =IF(ISBLANK(F2),J2/(G2*(1-H2)),F2) -> 4 | L2: =IF(ISBLANK(G2),J2/(F2*(1-H2)),G2) -> 849.21 | M2: =IF(ISBLANK(H2),1-(J2/(L2*F2)),H2) -> 0.07 | N2: =IF(ISBLANK(J2),F2*G2*(1-H2),J2) -> 3159.0612
A3: SALE426 | B3: 45462 | C3: CUST1175 | D3: PROD0 | E3: STORE16 | F3: 4 | G3: 897.93 | H3: 0.05 | I3: COD | J3: 3412.134 | K3: =IF(ISBLANK(F3),J3/(G3*(1-H3)),F3) -> 4 | L3: =IF(ISBLANK(G3),J3/(F3*(1-H3)),G3) -> 897.93 | M3: =IF(ISBLANK(H3),1-(J3/(L3*F3)),H3) -> 0.05 | N3: =IF(ISBLANK(J3),F3*G3*(1-H3),J3) -> 3412.134
A4: SALE514 | B4: 45312 | C4: CUST1129 | D4: PROD0 | E4: STORE7 | F4: 4 | G4: 191.65 | H4: 0.19 | I4: PayPal | J4: 620.946 | K4: =IF(ISBLANK(F4),J4/(G4*(1-H4)),F4) -> 4 | L4: =IF(ISBLANK(G4),J4/(F4*(1-H4)),G4) -> 191.65 | M4: =IF(ISBLANK(H4),1-(J4/(L4*F4)),H4) -> 0.19 | N4: =IF(ISBLANK(J4),F4*G4*(1-H4),J4) -> 620.946
A5: SALE1004 | B5: 45834 | C5: CUST1300 | D5: PROD0 | E5: STORE17 | F5: 1 | G5: 522.69 | H5: 0.06 | I5: COD | J5: 491.3286 | K5: =IF(ISBLANK(F5),J5/(G5*(1-H5)),F5) -> 1 | L5: =IF(ISBLANK(G5),J5/(F5*(1-H5)),G5) -> 522.69 | M5: =IF(ISBLANK(H5),1-(J5/(L5*F5)),H5) -> 0.06 | N5: =IF(ISBLANK(J5),F5*G5*(1-H5),J5) -> 491.3286
A6: SALE1097 | B6: 45596 | C6: CUST1071 | D6: PROD0 | E6: STORE3 | F6: 2 | G6: 374.42 | H6: 0.21 | I6: COD | J6: 591.5836 | K6: =IF(ISBLANK(F6),J6/(G6*(1-H6)),F6) -> 2 | L6: =IF(ISBLANK(G6),J6/(F6*(1-H6)),G6) -> 374.42 | M6: =IF(ISBLANK(H6),1-(J6/(L6*F6)),H6) -> 0.21 | N6: =IF(ISBLANK(J6),F6*G6*(1-H6),J6) -> 591.5836
A7: SALE1121 | B7: 45579 | C7: CUST1319 | D7: PROD0 | E7: STORE4 | F7: 3 | G7: 819.93 | H7: 0.08 | I7: PayPal | J7: 2263.0068 | K7: =IF(ISBLANK(F7),J7/(G7*(1-H7)),F7) -> 3 | L7: =IF(ISBLANK(G7),J7/(F7*(1-H7)),G7) -> 819.93 | M7: =IF(ISBLANK(H7),1-(J7/(L7*F7)),H7) -> 0.08 | N7: =IF(ISBLANK(J7),F7*G7*(1-H7),J7) -> 2263.0068
A8: SALE1126 | B8: 45653 | C8: CUST1379 | D8: PROD0 | E8: STORE17 | F8: 3 | G8: 241.64 | H8: 0.29 | I8: PayPal | J8: 514.6932 | K8: =IF(ISBLANK(F8),J8/(G8*(1-H8)),F8) -> 3 | L8: =IF(ISBLANK(G8),J8/(F8*(1-H8)),G8) -> 241.64 | M8: =IF(ISBLANK(H8),1-(J8/(L8*F8)),H8) -> 0.29 | N8: =IF(ISBLANK(J8),F8*G8*(1-H8),J8) -> 514.6932
A9: SALE1190 | B9: 45468 | C9: CUST1443 | D9: PROD0 | E9: STORE9 | F9: 2 | G9: 540.48 | H9: 0.29 | I9: Credit Card | J9: 767.4816 | K9: =IF(ISBLANK(F9),J9/(G9*(1-H9)),F9) -> 2 | L9: =IF(ISBLANK(G9),J9/(F9*(1-H9)),G9) -> 540.48 | M9: =IF(ISBLANK(H9),1-(J9/(L9*F9)),H9) -> 0.29 | N9: =IF(ISBLANK(J9),F9*G9*(1-H9),J9) -> 767.4816
A10: SALE1277 | B10: 45524 | C10: CUST1003 | D10: PROD0 | E10: STORE14 | F10: 1 | G10: 449.6 | H10: 0.01 | I10: PayPal | J10: 445.104 | K10: =IF(ISBLANK(F10),J10/(G10*(1-H10)),F10) -> 1 | L10: =IF(ISBLANK(G10),J10/(F10*(1-H10)),G10) -> 449.6 | M10: =IF(ISBLANK(H10),1-(J10/(L10*F10)),H10) -> 0.01 | N10: =IF(ISBLANK(J10),F10*G10*(1-H10),J10) -> 445.104
A11: SALE1286 | B11: 45810 | C11: CUST1365 | D11: PROD0 | E11: STORE16 | F11: 3 | G11: 279.45 | H11: 0.15 | I11: COD | J11: 712.5975 | K11: =IF(ISBLANK(F11),J11/(G11*(1-H11)),F11) -> 3 | L11: =IF(ISBLANK(G11),J11/(F11*(1-H11)),G11) -> 279.45 | M11: =IF(ISBLANK(H11),1-(J11/(L11*F11)),H11) -> 0.15 | N11: =IF(ISBLANK(J11),F11*G11*(1-H11),J11) -> 712.5975
A12: SALE1314 | B12: 45523 | C12: CUST1008 | D12: PROD0 | E12: STORE9 | F12: 2 | G12: 943.8 | H12: 0.06 | I12: Credit Card | J12: 1774.344 | K12: =IF(ISBLANK(F12),J12/(G12*(1-H12)),F12) -> 2 | L12: =IF(ISBLANK(G12),J12/(F12*(1-H12)),G12) -> 943.8 | M12: =IF(ISBLANK(H12),1-(J12/(L12*F12)),H12) -> 0.06 | N12: =IF(ISBLANK(J12),F12*G12*(1-H12),J12) -> 1774.344
A13: SALE1627 | B13: 45885 | C13: CUST1147 | D13: PROD0 | E13: STORE16 | F13: 3 | G13: 60.26 | H13: 0.04 | I13: Credit Card | J13: 173.5488 | K13: =IF(ISBLANK(F13),J13/(G13*(1-H13)),F13) -> 3 | L13: =IF(ISBLANK(G13),J13/(F13*(1-H13)),G13) -> 60.26 | M13: =IF(ISBLANK(H13),1-(J13/(L13*F13)),H13) -> 0.04 | N13: =IF(ISBLANK(J13),F13*G13*(1-H13),J13) -> 173.5488
... A132: SALE5 | B132: 45499 | C132: CUST1116 | D132: PROD15 | E132: STORE7 | F132: 3 | G132: 147.01 | H132: 0.19 | I132: COD | J132: 357.2343 | K132: =IF(ISBLANK(F132),J132/(G132*(1-H132)),F132) -> 3 | L132: =IF(ISBLANK(G132),J132/(F132*(1-H132)),G132) -> 147.01 | M132: =IF(ISBLANK(H132),1-(J132/(L132*F132)),H132) -> 0.19 | N132: =IF(ISBLANK(J132),F132*G132*(1-H132),J132) -> 357.2343
A133: SALE58 | B133: 45633 | C133: CUST1404 | D133: PROD15 | E133: STORE7 | F133: 4 | G133: 733.42 | I133: PayPal | J133: 2552.3016 | K133: =IF(ISBLANK(F133),J133/(G133*(1-H133)),F133) -> 4 | L133: =IF(ISBLANK(G133),J133/(F133*(1-H133)),G133) -> 733.42 | M133: =IF(ISBLANK(H133),1-(J133/(L133*F133)),H133) -> 0.13 | N133: =IF(ISBLANK(J133),F133*G133*(1-H133),J133) -> 2552.3016
A134: SALE217 | B134: 45219 | C134: CUST1266 | D134: PROD15 | E134: STORE19 | F134: 1 | G134: 332.82 | H134: 0.14 | I134: PayPal | J134: 286.2252 | K134: =IF(ISBLANK(F134),J134/(G134*(1-H134)),F134) -> 1 | L134: =IF(ISBLANK(G134),J134/(F134*(1-H134)),G134) -> 332.82 | M134: =IF(ISBLANK(H134),1-(J134/(L134*F134)),H134) -> 0.14 | N134: =IF(ISBLANK(J134),F134*G134*(1-H134),J134) -> 286.2252
A135: SALE238 | B135: 45253 | C135: CUST1135 | D135: PROD15 | E135: STORE5 | F135: 1 | G135: 594.44 | H135: 0.21 | I135: Credit Card | J135: 469.6076 | K135: =IF(ISBLANK(F135),J135/(G135*(1-H135)),F135) -> 1 | L135: =IF(ISBLANK(G135),J135/(F135*(1-H135)),G135) -> 594.44 | M135: =IF(ISBLANK(H135),1-(J135/(L135*F135)),H135) -> 0.21 | N135: =IF(ISBLANK(J135),F135*G135*(1-H135),J135) -> 469.6076
A136: SALE347 | B136: 45541 | C136: CUST1054 | D136: PROD15 | E136: STORE15 | F136: 2 | G136: 280.37 | H136: 0.22 | I136: COD | J136: 437.3772 | K136: =IF(ISBLANK(F136),J136/(G136*(1-H136)),F136) -> 2 | L136: =IF(ISBLANK(G136),J136/(F136*(1-H136)),G136) -> 280.37 | M136: =IF(ISBLANK(H136),1-(J136/(L136*F136)),H136) -> 0.22 | N136: =IF(ISBLANK(J136),F136*G136*(1-H136),J136) -> 437.3772
A137: SALE355 | B137: 45304 | C137: CUST1241 | D137: PROD15 | E137: STORE15 | F137: 2 | G137: 899.27 | H137: 0.17 | I137: Credit Card | J137: 1492.7882 | K137: =IF(ISBLANK(F137),J137/(G137*(1-H137)),F137) -> 2 | L137: =IF(ISBLANK(G137),J137/(F137*(1-H137)),G137) -> 899.27 | M137: =IF(ISBLANK(H137),1-(J137/(L137*F137)),H137) -> 0.17 | N137: =IF(ISBLANK(J137),F137*G137*(1-H137),J137) -> 1492.7882
A138: SALE409 | B138: 45837 | C138: CUST1327 | D138: PROD15 | E138: STORE16 | F138: 4 | G138: 370.63 | H138: 0.08 | I138: Credit Card | J138: 1363.9184 | K138: =IF(ISBLANK(F138),J138/(G138*(1-H138)),F138) -> 4 | L138: =IF(ISBLANK(G138),J138/(F138*(1-H138)),G138) -> 370.63 | M138: =IF(ISBLANK(H138),1-(J138/(L138*F138)),H138) -> 0.08 | N138: =IF(ISBLANK(J138),F138*G138*(1-H138),J138) -> 1363.9184
A139: SALE479 | B139: 45574 | C139: CUST1449 | D139: PROD15 | E139: STORE9 | F139: 3 | G139: 635.13 | H139: 0.09 | I139: PayPal | J139: 1733.9049 | K139: =IF(ISBLANK(F139),J139/(G139*(1-H139)),F139) -> 3 | L139: =IF(ISBLANK(G139),J139/(F139*(1-H139)),G139) -> 635.13 | M139: =IF(ISBLANK(H139),1-(J139/(L139*F139)),H139) -> 0.09 | N139: =IF(ISBLANK(J139),F139*G139*(1-H139),J139) -> 1733.9049
A140: SALE609 | B140: 45921 | C140: CUST1470 | D140: PROD15 | E140: STORE1 | F140: 4 | G140: 479.11 | H140: 0.24 | I140: PayPal | J140: 1456.4944 | K140: =IF(ISBLANK(F140),J140/(G140*(1-H140)),F140) -> 4 | L140: =IF(ISBLANK(G140),J140/(F140*(1-H140)),G140) -> 479.11 | M140: =IF(ISBLANK(H140),1-(J140/(L140*F140)),H140) -> 0.24 | N140: =IF(ISBLANK(J140),F140*G140*(1-H140),J140) -> 1456.4944
A141: SALE658 | B141: 45629 | C141: CUST1055 | D141: PROD15 | E141: STORE6 | F141: 2 | G141: 884.48 | H141: 0 | I141: COD | J141: 1768.96 | K141: =IF(ISBLANK(F141),J141/(G141*(1-H141)),F141) -> 2 | L141: =IF(ISBLANK(G141),J141/(F141*(1-H141)),G141) -> 884.48 | M141: =IF(ISBLANK(H141),1-(J141/(L141*F141)),H141) -> 0 | N141: =IF(ISBLANK(J141),F141*G141*(1-H141),J141) -> 1768.96
A142: SALE697 | B142: 45832 | C142: CUST1139 | D142: PROD15 | E142: STORE18 | F142: 2 | G142: 669.12 | H142: 0.22 | I142: Credit Card | J142: 1043.8272 | K142: =IF(ISBLANK(F142),J142/(G142*(1-H142)),F142) -> 2 | L142: =IF(ISBLANK(G142),J142/(F142*(1-H142)),G142) -> 669.12 | M142: =IF(ISBLANK(H142),1-(J142/(L142*F142)),H142) -> 0.22 | N142: =IF(ISBLANK(J142),F142*G142*(1-H142),J142) -> 1043.8272
A143: SALE703 | B143: 45429 | C143: CUST1196 | D143: PROD15 | E143: STORE16 | F143: 3 | G143: 262.69 | H143: 0.04 | I143: PayPal | J143: 756.5472 | K143: =IF(ISBLANK(F143),J143/(G143*(1-H143)),F143) -> 3 | L143: =IF(ISBLANK(G143),J143/(F143*(1-H143)),G143) -> 262.69 | M143: =IF(ISBLANK(H143),1-(J143/(L143*F143)),H143) -> 0.04 | N143: =IF(ISBLANK(J143),F143*G143*(1-H143),J143) -> 756.5472
A144: SALE722 | B144: 45379 | C144: CUST1241 | D144: PROD15 | E144: STORE14 | F144: 1 | G144: 31.36 | H144: 0.21 | I144: COD | J144: 24.7744 | K144: =IF(ISBLANK(F144),J144/(G144*(1-H144)),F144) -> 1 | L144: =IF(ISBLANK(G144),J144/(F144*(1-H144)),G144) -> 31.36 | M144: =IF(ISBLANK(H144),1-(J144/(L144*F144)),H144) -> 0.21 | N144: =IF(ISBLANK(J144),F144*G144*(1-H144),J144) -> 24.7744
A145: SALE914 | B145: 45308 | C145: CUST1039 | D145: PROD15 | E145: STORE19 | F145: 3 | G145: 620.12 | H145: 0.06 | I145: Credit Card | J145: 1748.7384 | K145: =IF(ISBLANK(F145),J145/(G145*(1-H145)),F145) -> 3 | L145: =IF(ISBLANK(G145),J145/(F145*(1-H145)),G145) -> 620.12 | M145: =IF(ISBLANK(H145),1-(J145/(L145*F145)),H145) -> 0.06 | N145: =IF(ISBLANK(J145),F145*G145*(1-H145),J145) -> 1748.7384
... A585: SALE258 | B585: 45300 | C585: CUST1136 | D585: PROD35 | E585: STORE17 | F585: 1 | G585: 222.94 | H585: 0.19 | I585: Credit Card | J585: 180.5814 | K585: =IF(ISBLANK(F585),J585/(G585*(1-H585)),F585) -> 1 | L585: =IF(ISBLANK(G585),J585/(F585*(1-H585)),G585) -> 222.94 | M585: =IF(ISBLANK(H585),1-(J585/(L585*F585)),H585) -> 0.19 | N585: =IF(ISBLANK(J585),F585*G585*(1-H585),J585) -> 180.5814
A586: SALE259 | B586: 45773 | C586: CUST1248 | D586: PROD35 | E586: STORE2 | F586: 2 | G586: 355.3 | I586: PayPal | J586: 589.798 | K586: =IF(ISBLANK(F586),J586/(G586*(1-H586)),F586) -> 2 | L586: =IF(ISBLANK(G586),J586/(F586*(1-H586)),G586) -> 355.3 | M586: =IF(ISBLANK(H586),1-(J586/(L586*F586)),H586) -> 0.17 | N586: =IF(ISBLANK(J586),F586*G586*(1-H586),J586) -> 589.798
A587: SALE364 | B587: 45723 | C587: CUST1216 | D587: PROD35 | E587: STORE18 | F587: 1 | G587: 213.69 | H587: 0.28 | I587: COD | J587: 153.8568 | K587: =IF(ISBLANK(F587),J587/(G587*(1-H587)),F587) -> 1 | L587: =IF(ISBLANK(G587),J587/(F587*(1-H587)),G587) -> 213.69 | M587: =IF(ISBLANK(H587),1-(J587/(L587*F587)),H587) -> 0.28 | N587: =IF(ISBLANK(J587),F587*G587*(1-H587),J587) -> 153.8568
A588: SALE543 | B588: 45711 | C588: CUST1333 | D588: PROD35 | E588: STORE6 | F588: 1 | G588: 763.34 | H588: 0.11 | I588: COD | J588: 679.3726 | K588: =IF(ISBLANK(F588),J588/(G588*(1-H588)),F588) -> 1 | L588: =IF(ISBLANK(G588),J588/(F588*(1-H588)),G588) -> 763.34 | M588: =IF(ISBLANK(H588),1-(J588/(L588*F588)),H588) -> 0.11 | N588: =IF(ISBLANK(J588),F588*G588*(1-H588),J588) -> 679.3726
A589: SALE946 | B589: 45600 | C589: CUST1140 | D589: PROD35 | E589: STORE1 | F589: 2 | G589: 157.18 | H589: 0.15 | I589: Credit Card | J589: 267.206 | K589: =IF(ISBLANK(F589),J589/(G589*(1-H589)),F589) -> 2 | L589: =IF(ISBLANK(G589),J589/(F589*(1-H589)),G589) -> 157.18 | M589: =IF(ISBLANK(H589),1-(J589/(L589*F589)),H589) -> 0.15 | N589: =IF(ISBLANK(J589),F589*G589*(1-H589),J589) -> 267.206
A590: SALE1054 | B590: 45850 | C590: CUST1437 | D590: PROD35 | E590: STORE12 | F590: 3 | G590: 471.31 | H590: 0 | I590: PayPal | J590: 1413.93 | K590: =IF(ISBLANK(F590),J590/(G590*(1-H590)),F590) -> 3 | L590: =IF(ISBLANK(G590),J590/(F590*(1-H590)),G590) -> 471.31 | M590: =IF(ISBLANK(H590),1-(J590/(L590*F590)),H590) -> 0 | N590: =IF(ISBLANK(J590),F590*G590*(1-H590),J590) -> 1413.93
A591: SALE1165 | B591: 45251 | C591: CUST1243 | D591: PROD35 | E591: STORE0 | F591: 2 | G591: 961.68 | H591: 0.27 | I591: PayPal | J591: 1404.0528 | K591: =IF(ISBLANK(F591),J591/(G591*(1-H591)),F591) -> 2 | L591: =IF(ISBLANK(G591),J591/(F591*(1-H591)),G591) -> 961.68 | M591: =IF(ISBLANK(H591),1-(J591/(L591*F591)),H591) -> 0.27 | N591: =IF(ISBLANK(J591),F591*G591*(1-H591),J591) -> 1404.0528
A592: SALE1211 | B592: 45558 | C592: CUST1015 | D592: PROD35 | E592: STORE6 | F592: 4 | G592: 328.27 | H592: 0.09 | I592: PayPal | J592: 1194.9028 | K592: =IF(ISBLANK(F592),J592/(G592*(1-H592)),F592) -> 4 | L592: =IF(ISBLANK(G592),J592/(F592*(1-H592)),G592) -> 328.27 | M592: =IF(ISBLANK(H592),1-(J592/(L592*F592)),H592) -> 0.09 | N592: =IF(ISBLANK(J592),F592*G592*(1-H592),J592) -> 1194.9028
A593: SALE1219 | B593: 45905 | C593: CUST1030 | D593: PROD35 | E593: STORE15 | F593: 4 | G593: 642.05 | H593: 0.25 | I593: Credit Card | J593: 1926.15 | K593: =IF(ISBLANK(F593),J593/(G593*(1-H593)),F593) -> 4 | L593: =IF(ISBLANK(G593),J593/(F593*(1-H593)),G593) -> 642.05 | M593: =IF(ISBLANK(H593),1-(J593/(L593*F593)),H593) -> 0.25 | N593: =IF(ISBLANK(J593),F593*G593*(1-H593),J593) -> 1926.15
A594: SALE1369 | B594: 45798 | C594: CUST1005 | D594: PROD35 | E594: STORE7 | F594: 4 | G594: 185.67 | H594: 0.21 | I594: PayPal | J594: 586.7172 | K594: =IF(ISBLANK(F594),J594/(G594*(1-H594)),F594) -> 4 | L594: =IF(ISBLANK(G594),J594/(F594*(1-H594)),G594) -> 185.67 | M594: =IF(ISBLANK(H594),1-(J594/(L594*F594)),H594) -> 0.21 | N594: =IF(ISBLANK(J594),F594*G594*(1-H594),J594) -> 586.7172
A595: SALE1410 | B595: 45760 | C595: CUST1144 | D595: PROD35 | E595: STORE4 | F595: 2 | G595: 326.85 | H595: 0.17 | I595: COD | J595: 542.571 | K595: =IF(ISBLANK(F595),J595/(G595*(1-H595)),F595) -> 2 | L595: =IF(ISBLANK(G595),J595/(F595*(1-H595)),G595) -> 326.85 | M595: =IF(ISBLANK(H595),1-(J595/(L595*F595)),H595) -> 0.17 | N595: =IF(ISBLANK(J595),F595*G595*(1-H595),J595) -> 542.571
A596: SALE1451 | B596: 45383 | C596: CUST1005 | D596: PROD35 | E596: STORE18 | F596: 3 | G596: 341.51 | H596: 0.22 | I596: COD | J596: 799.1334 | K596: =IF(ISBLANK(F596),J596/(G596*(1-H596)),F596) -> 3 | L596: =IF(ISBLANK(G596),J596/(F596*(1-H596)),G596) -> 341.51 | M596: =IF(ISBLANK(H596),1-(J596/(L596*F596)),H596) -> 0.22 | N596: =IF(ISBLANK(J596),F596*G596*(1-H596),J596) -> 799.1334
A597: SALE1506 | B597: 45864 | C597: CUST1469 | D597: PROD35 | E597: STORE8 | F597: 4 | G597: 480.75 | H597: 0.02 | I597: Credit Card | J597: 1884.54 | K597: =IF(ISBLANK(F597),J597/(G597*(1-H597)),F597) -> 4 | L597: =IF(ISBLANK(G597),J597/(F597*(1-H597)),G597) -> 480.75 | M597: =IF(ISBLANK(H597),1-(J597/(L597*F597)),H597) -> 0.02 | N597: =IF(ISBLANK(J597),F597*G597*(1-H597),J597) -> 1884.54
...

Sheet Customer_Loyalty level
A1: Row Labels | B1: Average of Total_Amount | C1: Sum of Total_Amount | D1: Sum of Quantity | E1: Max of Discount | F1: Max of Order_Date | G1: Loyalty_Level
A2: CUST1219 | B2: 1714.7713 | C2: 17147.713 | D2: 29 | E2: 0.24 | F2: 45854 | G2: =VLOOKUP(A2,Customer_Dim!$A$1:$H$501,8,0) -> Gold
A3: CUST1084 | B3: 1934.6377 | C3: 15477.101 | D3: 27 | E3: 0.29 | F3: 45906 | G3: =VLOOKUP(A3,Customer_Dim!$A$1:$H$501,8,0) -> Platinum
A4: CUST1057 | B4: 1850.4244 | C4: 14803.395 | D4: 24 | E4: 0.27 | F4: 45859 | G4: =VLOOKUP(A4,Customer_Dim!$A$1:$H$501,8,0) -> Platinum
A5: CUST1319 | B5: 1945.7693 | C5: 13620.385 | D5: 17 | E5: 0.19 | F5: 45579 | G5: =VLOOKUP(A5,Customer_Dim!$A$1:$H$501,8,0) -> Platinum
A6: CUST1067 | B6: 1361.0902 | C6: 13610.902 | D6: 23 | E6: 0.3 | F6: 45873 | G6: =VLOOKUP(A6,Customer_Dim!$A$1:$H$501,8,0) -> Silver
A7: CUST1168 | B7: 1467.6159 | C7: 13208.543 | D7: 25 | E7: 0.28 | F7: 45929 | G7: =VLOOKUP(A7,Customer_Dim!$A$1:$H$501,8,0) -> Platinum
A8: CUST1013 | B8: 1857.9667 | C8: 13005.767 | D8: 24 | E8: 0.22 | F8: 45764 | G8: =VLOOKUP(A8,Customer_Dim!$A$1:$H$501,8,0) -> Silver
A9: CUST1485 | B9: 1808.1438 | C9: 12657.007 | D9: 22 | E9: 0.3 | F9: 45864 | G9: =VLOOKUP(A9,Customer_Dim!$A$1:$H$501,8,0) -> Bronze
A10: CUST1470 | B10: 1712.3642 | C10: 11986.55 | D10: 25 | E10: 0.3 | F10: 45921 | G10: =VLOOKUP(A10,Customer_Dim!$A$1:$H$501,8,0) -> Gold
A11: CUST1054 | B11: 1315.2058 | C11: 11836.852 | D11: 30 | E11: 0.25 | F11: 45862 | G11: =VLOOKUP(A11,Customer_Dim!$A$1:$H$501,8,0) -> Platinum
A12: CUST1051 | B12: 1467.7466 | C12: 11741.973 | D12: 25 | E12: 0.3 | F12: 45886 | G12: =VLOOKUP(A12,Customer_Dim!$A$1:$H$501,8,0) -> Gold
A13: CUST1161 | B13: 1637.1794 | C13: 11460.256 | D13: 18 | E13: 0.24 | F13: 45773 | G13: =VLOOKUP(A13,Customer_Dim!$A$1:$H$501,8,0) -> Silver
... A493: CUST1340 | B493: 36.0272 | C493: 36.0272 | D493: 2 | E493: 0.12 | F493: 45556 | G493: =VLOOKUP(A493,Customer_Dim!$A$1:$H$501,8,0) -> Bronze
A494: Grand Total | B494: 1087.1973 | C494: 2174394.7 | D494: 4964 | E494: 0.3 | F494: 45943

Sheet Ref sheet
A1: Product_ID | B1: Store_ID | C1: Quantity | D1: Unit_Price | E1: Discount | F1: Payment_Type | G1: Total_Amount Imputed
A2: PROD97 | B2: STORE3 | C2: 1 | D2: 218.04 | E2: 0.09 | F2: Credit Card | G2: 198.4164
A3: PROD74 | B3: STORE17 | C3: 3 | D3: 104.47 | E3: 0.27 | F3: PayPal | G3: 228.7893
A4: PROD49 | B4: STORE8 | C4: 4 | D4: 914.05 | E4: 0.25 | F4: Credit Card | G4: 2742.15
A5: PROD76 | B5: STORE8 | C5: 1 | D5: 921.51 | E5: 0.16 | F5: COD | G5: 774.0684
A6: PROD59 | B6: STORE5 | C6: 3 | D6: 745.3 | E6: 0.18 | F6: Credit Card | G6: 1833.438
A7: PROD15 | B7: STORE7 | C7: 3 | D7: 147.01 | E7: 0.19 | F7: COD | G7: 357.2343
A8: PROD56 | B8: STORE4 | C8: 2 | D8: 785.31 | E8: 0.15 | F8: PayPal | G8: 1335.027
A9: PROD70 | B9: STORE8 | C9: 4 | D9: 342.39 | E9: 0.23 | F9: PayPal | G9: 1054.5612
A10: PROD99 | B10: STORE5 | C10: 3 | D10: 448.25 | E10: 0.07 | F10: PayPal | G10: 1250.6175
A11: PROD33 | B11: STORE0 | C11: 2 | D11: 873.17 | E11: 0.23 | F11: PayPal | G11: 1344.6818
A12: PROD24 | B12: STORE14 | C12: 1 | D12: 278.63 | E12: 0.07 | F12: Credit Card | G12: 259.1259
A13: PROD39 | B13: STORE1 | C13: 4 | D13: 286.92 | E13: 0.17 | F13: Credit Card | G13: 952.5744
... A20: PROD39 | B20: STORE4 | C20: 2 | D20: 559.23 | E20: 0.25 | F20: COD | G20: 838.845
A21: PROD60 | B21: STORE13 | C21: 4 | E21: 0.04 | F21: COD | G21: 1782.4512
A22: PROD72 | B22: STORE17 | C22: 3 | D22: 986.04 | E22: 0.27 | F22: COD | G22: 2159.4276
A23: PROD43 | B23: STORE18 | C23: 1 | D23: 589.56 | E23: 0.22 | F23: Credit Card | G23: 459.8568
A24: PROD69 | B24: STORE10 | C24: 3 | D24: 979.42 | E24: 0.03 | F24: PayPal | G24: 2850.1122
A25: PROD12 | B25: STORE8 | C25: 1 | D25: 719.28 | E25: 0.08 | F25: Credit Card | G25: 661.7376
A26: PROD67 | B26: STORE6 | C26: 3 | D26: 77.6 | E26: 0.07 | F26: Credit Card | G26: 216.504
A27: PROD5 | B27: STORE3 | C27: 4 | D27: 852.71 | E27: 0.14 | F27: PayPal | G27: 2933.3224
A28: PROD98 | B28: STORE8 | C28: 4 | D28: 156.16 | F28: Credit Card | G28: 599.6544
A29: PROD77 | B29: STORE8 | C29: 3 | D29: 815.49 | E29: 0.17 | F29: Credit Card | G29: 2030.5701
A30: PROD13 | B30: STORE2 | C30: 2 | D30: 74.21 | E30: 0.11 | F30: PayPal | G30: 132.0938
A31: PROD99 | B31: STORE3 | C31: 4 | D31: 451.67 | E31: 0.15 | F31: Credit Card | G31: 1535.678
A32: PROD5 | B32: STORE19 | C32: 1 | D32: 429.38 | E32: 0.13 | F32: PayPal | G32: 373.5606
A33: PROD53 | B33: STORE12 | C33: 2 | D33: 148.96 | E33: 0.03 | F33: COD | G33: 288.9824
A34: PROD75 | B34: STORE8 | C34: 4 | D34: 313.83 | E34: 0.08 | F34: Credit Card | G34: 1154.8944
A35: PROD12 | B35: STORE6 | C35: 2 | D35: 717.31 | E35: 0.15 | F35: Credit Card | G35: 1219.427
A36: PROD79 | B36: STORE1 | C36: 3 | D36: 873.22 | E36: 0.18 | F36: Credit Card | G36: 2148.1212
A37: PROD16 | B37: STORE3 | C37: 4 | D37: 109.36 | E37: 0.19 | F37: COD | G37: 354.3264
A38: PROD5 | B38: STORE7 | C38: 3 | D38: 559.52 | E38: 0.16 | F38: PayPal | G38: 1409.9904
A39: PROD10 | B39: STORE17 | C39: 3 | D39: 121.76 | E39: 0.27 | F39: PayPal | G39: 266.6544
A40: PROD33 | B40: STORE13 | C40: 4 | D40: 735.32 | E40: 0.06 | F40: COD | G40: 2764.8032
... A53: PROD69 | B53: STORE7 | C53: 3 | D53: 76.57 | E53: 0.26 | F53: Credit Card | G53: 169.9854
A54: PROD89 | B54: STORE6 | C54: 3 | F54: Credit Card | G54: 486.0633
A55: PROD20 | B55: STORE8 | C55: 1 | D55: 900.35 | E55: 0.13 | F55: COD | G55: 783.3045
A56: PROD40 | B56: STORE10 | C56: 4 | D56: 428.09 | E56: 0.07 | F56: Credit Card | G56: 1592.4948
A57: PROD49 | B57: STORE11 | C57: 2 | D57: 559.71 | E57: 0.3 | F57: COD | G57: 783.594
A58: PROD34 | B58: STORE6 | C58: 2 | D58: 833.7 | E58: 0.06 | F58: PayPal | G58: 1567.356
...

Sheet Mean - Meadian - Mode
A1: Row Labels | B1: Sum of Sum of Total_Amount | C1: Age | D1: Age group | E1: Gender | F1: State | I1: Age | M1: Sales amount
A2: CUST1000 | B2: 2437.6722 | C2: =VLOOKUP(A2,Customer_Dim!$A$2:$H$501,3,0) -> 55 | D2: =IF(C2<20,"Below 20", IF(C2<40,"20–39", IF(C2<60,"40–59","60+"))) -> 40–59 | E2: =VLOOKUP(A2,Customer_Dim!$A$2:$H$501,4,0) -> Male | F2: =VLOOKUP(A2,Customer_Dim!$A$2:$H$501,6,0) -> North Carolina | I2: Mean | J2: =AVERAGE(C2:C493) -> 41.571138 | M2: Mean | N2: =AVERAGE(B2:B494) -> 8821.0738
A3: CUST1001 | B3: 1941.1877 | C3: =VLOOKUP(A3,Customer_Dim!$A$2:$H$501,3,0) -> 26 | D3: =IF(C3<20,"Below 20", IF(C3<40,"20–39", IF(C3<60,"40–59","60+"))) -> 20–39 | E3: =VLOOKUP(A3,Customer_Dim!$A$2:$H$501,4,0) -> Female | F3: =VLOOKUP(A3,Customer_Dim!$A$2:$H$501,6,0) -> North Dakota | I3: Median | J3: =MEDIAN(C2:C492) -> 42 | M3: Median | N3: =MEDIAN(B3:B495) -> 4002.9356
A4: CUST1002 | B4: 2078.4183 | C4: =VLOOKUP(A4,Customer_Dim!$A$2:$H$501,3,0) -> 29 | D4: =IF(C4<20,"Below 20", IF(C4<40,"20–39", IF(C4<60,"40–59","60+"))) -> 20–39 | E4: =VLOOKUP(A4,Customer_Dim!$A$2:$H$501,4,0) -> Female | F4: =VLOOKUP(A4,Customer_Dim!$A$2:$H$501,6,0) -> Alabama | I4: Mode | J4: =MODE(C2:C493) -> 46 | M4: SD | N4: =STDEV(B4:B496) -> 218771.12
A5: CUST1003 | B5: 2330.867 | C5: =VLOOKUP(A5,Customer_Dim!$A$2:$H$501,3,0) -> 59 | D5: =IF(C5<20,"Below 20", IF(C5<40,"20–39", IF(C5<60,"40–59","60+"))) -> 40–59 | E5: =VLOOKUP(A5,Customer_Dim!$A$2:$H$501,4,0) -> Female | F5: =VLOOKUP(A5,Customer_Dim!$A$2:$H$501,6,0) -> Ohio
A6: CUST1004 | B6: 5830.6476 | C6: =VLOOKUP(A6,Customer_Dim!$A$2:$H$501,3,0) -> 64 | D6: =IF(C6<20,"Below 20", IF(C6<40,"20–39", IF(C6<60,"40–59","60+"))) -> 60+ | E6: =VLOOKUP(A6,Customer_Dim!$A$2:$H$501,4,0) -> Female | F6: =VLOOKUP(A6,Customer_Dim!$A$2:$H$501,6,0) -> California
A7: CUST1005 | B7: 4795.0978 | C7: =VLOOKUP(A7,Customer_Dim!$A$2:$H$501,3,0) -> 24 | D7: =IF(C7<20,"Below 20", IF(C7<40,"20–39", IF(C7<60,"40–59","60+"))) -> 20–39 | E7: =VLOOKUP(A7,Customer_Dim!$A$2:$H$501,4,0) -> Male | F7: =VLOOKUP(A7,Customer_Dim!$A$2:$H$501,6,0) -> Oregon
A8: CUST1006 | B8: 6348.0162 | C8: =VLOOKUP(A8,Customer_Dim!$A$2:$H$501,3,0) -> 29 | D8: =IF(C8<20,"Below 20", IF(C8<40,"20–39", IF(C8<60,"40–59","60+"))) -> 20–39 | E8: =VLOOKUP(A8,Customer_Dim!$A$2:$H$501,4,0) -> Female | F8: =VLOOKUP(A8,Customer_Dim!$A$2:$H$501,6,0) -> South Dakota
A9: CUST1007 | B9: 10211.024 | C9: =VLOOKUP(A9,Customer_Dim!$A$2:$H$501,3,0) -> 29 | D9: =IF(C9<20,"Below 20", IF(C9<40,"20–39", IF(C9<60,"40–59","60+"))) -> 20–39 | E9: =VLOOKUP(A9,Customer_Dim!$A$2:$H$501,4,0) -> Female | F9: =VLOOKUP(A9,Customer_Dim!$A$2:$H$501,6,0) -> West Virginia
A10: CUST1008 | B10: 4029.7085 | C10: =VLOOKUP(A10,Customer_Dim!$A$2:$H$501,3,0) -> 53 | D10: =IF(C10<20,"Below 20", IF(C10<40,"20–39", IF(C10<60,"40–59","60+"))) -> 40–59 | E10: =VLOOKUP(A10,Customer_Dim!$A$2:$H$501,4,0) -> Female | F10: =VLOOKUP(A10,Customer_Dim!$A$2:$H$501,6,0) -> New Hampshire
A11: CUST1009 | B11: 3903.6052 | C11: =VLOOKUP(A11,Customer_Dim!$A$2:$H$501,3,0) -> 64 | D11: =IF(C11<20,"Below 20", IF(C11<40,"20–39", IF(C11<60,"40–59","60+"))) -> 60+ | E11: =VLOOKUP(A11,Customer_Dim!$A$2:$H$501,4,0) -> Male | F11: =VLOOKUP(A11,Customer_Dim!$A$2:$H$501,6,0) -> Pennsylvania
A12: CUST1010 | B12: 2235.5459 | C12: =VLOOKUP(A12,Customer_Dim!$A$2:$H$501,3,0) -> 53 | D12: =IF(C12<20,"Below 20", IF(C12<40,"20–39", IF(C12<60,"40–59","60+"))) -> 40–59 | E12: =VLOOKUP(A12,Customer_Dim!$A$2:$H$501,4,0) -> Male | F12: =VLOOKUP(A12,Customer_Dim!$A$2:$H$501,6,0) -> Pennsylvania
A13: CUST1011 | B13: 3868.3903 | C13: =VLOOKUP(A13,Customer_Dim!$A$2:$H$501,3,0) -> 28 | D13: =IF(C13<20,"Below 20", IF(C13<40,"20–39", IF(C13<60,"40–59","60+"))) -> 20–39 | E13: =VLOOKUP(A13,Customer_Dim!$A$2:$H$501,4,0) -> Female | F13: =VLOOKUP(A13,Customer_Dim!$A$2:$H$501,6,0) -> New York
A14: CUST1012 | B14: 7752.779 | C14: =VLOOKUP(A14,Customer_Dim!$A$2:$H$501,3,0) -> 55 | D14: =IF(C14<20,"Below 20", IF(C14<40,"20–39", IF(C14<60,"40–59","60+"))) -> 40–59 | E14: =VLOOKUP(A14,Customer_Dim!$A$2:$H$501,4,0) -> Female | F14: =VLOOKUP(A14,Customer_Dim!$A$2:$H$501,6,0) -> Kansas
A15: CUST1013 | B15: 13005.767 | C15: =VLOOKUP(A15,Customer_Dim!$A$2:$H$501,3,0) -> 32 | D15: =IF(C15<20,"Below 20", IF(C15<40,"20–39", IF(C15<60,"40–59","60+"))) -> 20–39 | E15: =VLOOKUP(A15,Customer_Dim!$A$2:$H$501,4,0) -> Female | F15: =VLOOKUP(A15,Customer_Dim!$A$2:$H$501,6,0) -> Montana
A16: CUST1014 | B16: 2365.2003 | C16: =VLOOKUP(A16,Customer_Dim!$A$2:$H$501,3,0) -> 53 | D16: =IF(C16<20,"Below 20", IF(C16<40,"20–39", IF(C16<60,"40–59","60+"))) -> 40–59 | E16: =VLOOKUP(A16,Customer_Dim!$A$2:$H$501,4,0) -> Female | F16: =VLOOKUP(A16,Customer_Dim!$A$2:$H$501,6,0) -> Nebraska
... A493: CUST1499 | B493: 5661.8447 | C493: =VLOOKUP(A493,Customer_Dim!$A$2:$H$501,3,0) -> 27 | D493: =IF(C493<20,"Below 20", IF(C493<40,"20–39", IF(C493<60,"40–59","60+"))) -> 20–39 | E493: =VLOOKUP(A493,Customer_Dim!$A$2:$H$501,4,0) -> Female | F493: =VLOOKUP(A493,Customer_Dim!$A$2:$H$501,6,0) -> Oregon
A494: Grand Total | B494: 2174394.7
A495: Grand Total | B495: 4348789.4

Sheet Product - Sales
A1: Product ID | B1: Sum of Total_Amount | C1: Sum of Quantity | D1: Product_Name
A2: PROD39 | B2: 41852.503 | C2: 84 | D2: =VLOOKUP(A2,Product_Dim!$A$1:$G$101,2,0) -> Portable Power Bank
A3: PROD73 | B3: 38281.015 | C3: 77 | D3: =VLOOKUP(A3,Product_Dim!$A$1:$G$101,2,0) -> Shin Guards – Adult
A4: PROD37 | B4: 35489.62 | C4: 87 | D4: =VLOOKUP(A4,Product_Dim!$A$1:$G$101,2,0) -> Men's Casual Sneakers
A5: PROD34 | B5: 34699.833 | C5: 84 | D5: =VLOOKUP(A5,Product_Dim!$A$1:$G$101,2,0) -> Gaming Mechanical Keyboard
A6: PROD91 | B6: 33993.659 | C6: 67 | D6: =VLOOKUP(A6,Product_Dim!$A$1:$G$101,2,0) -> Women's High Heels
A7: PROD76 | B7: 33566.8 | C7: 73 | D7: =VLOOKUP(A7,Product_Dim!$A$1:$G$101,2,0) -> Wireless Mouse
A8: PROD31 | B8: 31070.456 | C8: 63 | D8: =VLOOKUP(A8,Product_Dim!$A$1:$G$101,2,0) -> Basketball
A9: PROD59 | B9: 30236.698 | C9: 66 | D9: =VLOOKUP(A9,Product_Dim!$A$1:$G$101,2,0) -> Men's Hair Styling Gel
A10: PROD96 | B10: 28572.692 | C10: 45 | D10: =VLOOKUP(A10,Product_Dim!$A$1:$G$101,2,0) -> Women's Formal Blazer
A11: PROD17 | B11: 28324.049 | C11: 70 | D11: =VLOOKUP(A11,Product_Dim!$A$1:$G$101,2,0) -> Soccer Training Cone Set
A12: PROD15 | B12: 28285.614 | C12: 72 | D12: =VLOOKUP(A12,Product_Dim!$A$1:$G$101,2,0) -> 4K Home Projector
A13: PROD89 | B13: 28237.931 | C13: 68 | D13: =VLOOKUP(A13,Product_Dim!$A$1:$G$101,2,0) -> Face Foundation Kit
... A101: PROD47 | B101: 7948.3905 | C101: 29 | D101: =VLOOKUP(A101,Product_Dim!$A$1:$G$101,2,0) -> Makeup Brush Set
A102: Grand Total | B102: 2174394.7 | C102: 4964

Sheet Store - Sales
A1: Sum of Total_Amount Imputed
A2: Store ID | B2: COD | C2: Credit Card | D2: PayPal | E2: Total sales | F2: Store name
A3: STORE8 | B3: 34142.73 | C3: 72215.371 | D3: 52613.361 | E3: 158971.46 | F3: =VLOOKUP(A3,Store_Dim!$A$1:$E$21,2,0) -> Bean, Jones and Park
A4: STORE3 | B4: 33446.974 | C4: 46541.045 | D4: 45023.81 | E4: 125011.83 | F4: =VLOOKUP(A4,Store_Dim!$A$1:$E$21,2,0) -> Johnson-Wright
A5: STORE17 | B5: 38114.378 | C5: 33813.865 | D5: 50248.304 | E5: 122176.55 | F5: =VLOOKUP(A5,Store_Dim!$A$1:$E$21,2,0) -> Holloway Ltd
A6: STORE4 | B6: 24588.907 | C6: 45275.221 | D6: 48949.988 | E6: 118814.12 | F6: =VLOOKUP(A6,Store_Dim!$A$1:$E$21,2,0) -> Alexander Group
A7: STORE12 | B7: 31116.781 | C7: 53805.05 | D7: 31907.39 | E7: 116829.22 | F7: =VLOOKUP(A7,Store_Dim!$A$1:$E$21,2,0) -> Thomas, Bridges and Harris
A8: STORE6 | B8: 36767.687 | C8: 34688.908 | D8: 43077.202 | E8: 114533.8 | F8: =VLOOKUP(A8,Store_Dim!$A$1:$E$21,2,0) -> Benson-Elliott
A9: STORE13 | B9: 42434.351 | C9: 37172.494 | D9: 34794.627 | E9: 114401.47 | F9: =VLOOKUP(A9,Store_Dim!$A$1:$E$21,2,0) -> Gardner, Humphrey and Contreras
A10: STORE16 | B10: 47433.617 | C10: 33648.204 | D10: 30623.122 | E10: 111704.94 | F10: =VLOOKUP(A10,Store_Dim!$A$1:$E$21,2,0) -> Frederick-Wright
A11: STORE9 | B11: 42363.084 | C11: 37845.537 | D11: 29893.777 | E11: 110102.4 | F11: =VLOOKUP(A11,Store_Dim!$A$1:$E$21,2,0) -> Moore, Padilla and Butler
A12: STORE10 | B12: 44329.974 | C12: 31658.845 | D12: 33802.896 | E12: 109791.72 | F12: =VLOOKUP(A12,Store_Dim!$A$1:$E$21,2,0) -> Hill, Wagner and Ballard
A13: STORE7 | B13: 34217.123 | C13: 26907.143 | D13: 46915.083 | E13: 108039.35 | F13: =VLOOKUP(A13,Store_Dim!$A$1:$E$21,2,0) -> Martinez-Mullins
A14: STORE14 | B14: 36010.408 | C14: 34124.633 | D14: 36113.243 | E14: 106248.28 | F14: =VLOOKUP(A14,Store_Dim!$A$1:$E$21,2,0) -> Mcdonald Inc
... A22: STORE5 | B22: 31307.002 | C22: 25208.608 | D22: 24827.98 | E22: 81343.589 | F22: =VLOOKUP(A22,Store_Dim!$A$1:$E$21,2,0) -> Gray Ltd
A23: Total sales | B23: 702459.42 | C23: 715180.71 | D23: 756754.57 | E23: 2174394.7

Sheet Stocks
A3: Row Labels | B3: Sum of Stock
A4: Beauty | B4: 4816
A5: Clothing | B5: 4931
A6: Electronics | B6: 5494
A7: Home | B7: 4521
A8: Sports | B8: 6767
A9: Grand Total | B9: 26529

Sheet Store - sales - Pivot tables
A1: Row Labels | B1: Sum of Total_Amount
A2: STORE0 | B2: 85138.555
A3: STORE1 | B3: 101060.61
A4: STORE10 | B4: 109791.72
A5: STORE11 | B5: 93048.14
A6: STORE12 | B6: 116829.22
A7: STORE13 | B7: 114401.47
A8: STORE14 | B8: 106248.28
A9: STORE15 | B9: 99679.086
A10: STORE16 | B10: 111704.94
A11: STORE17 | B11: 122176.55
A12: STORE18 | B12: 104313.05
A13: STORE19 | B13: 94225.723
... A22: Grand Total | B22: 2174394.7
A23: Row Labels | B23: Count of Store_ID
A24: COD | B24: 660
A25: Credit Card | B25: 645
A26: PayPal | B26: 695
A27: Grand Total | B27: 2000
A29: Row Labels | B29: Sum of Quantity
A30: STORE0 | B30: 204
A31: STORE1 | B31: 232
A32: STORE10 | B32: 255
A33: STORE11 | B33: 206
A34: STORE12 | B34: 259
A35: STORE13 | B35: 243
A36: STORE14 | B36: 224
A37: STORE15 | B37: 243
A38: STORE16 | B38: 249
A39: STORE17 | B39: 277
A40: STORE18 | B40: 247
A41: STORE19 | B41: 240
... A50: Grand Total | B50: 4964

Sheet Store Sales Dashboard
A1: STORE Sales Dashboard | W1: Product Sales Dashboard

Sheet Product - sales - table
A1: Sales_ID | B1: Order_Date | C1: Customer_ID | D1: Product_ID | E1: Product name | F1: Store_ID | G1: Quantity | H1: Unit_Price | I1: Discount | J1: Payment_Type | K1: Total_Amount | L1: Age | M1: Age group | N1: Gender | O1: State | P1: Stock
A2: SALE992 | B2: 45575 | C2: CUST1000 | D2: PROD40 | E2: =VLOOKUP(D2,Product_Dim!$A$1:$G$101,2,0) -> Noise-Canceling Headphones | F2: STORE7 | G2: 3 | H2: 490.02 | I2: 0.26 | J2: Credit Card | K2: 1087.8444 | L2: =VLOOKUP(C2,Customer_Dim!$A$2:$H$501,3,0) -> 55 | M2: =IF(L2<20,"Below 20", IF(L2<40,"20–39", IF(L2<60,"40–59","60+"))) -> 40–59 | N2: =VLOOKUP(C2,Customer_Dim!$A$2:$H$501,4,0) -> Male | O2: =VLOOKUP(C2,Customer_Dim!$A$2:$H$501,6,0) -> North Carolina | P2: =VLOOKUP(D2,Product_Dim!$A$1:$G$101,7,0) -> 378
A3: SALE902 | B3: 45812 | C3: CUST1000 | D3: PROD56 | E3: =VLOOKUP(D3,Product_Dim!$A$1:$G$101,2,0) -> Premium Blanket Throw | F3: STORE19 | G3: 2 | H3: 404.08 | I3: 0.07 | J3: Credit Card | K3: 751.5888 | L3: =VLOOKUP(C3,Customer_Dim!$A$2:$H$501,3,0) -> 55 | M3: =IF(L3<20,"Below 20", IF(L3<40,"20–39", IF(L3<60,"40–59","60+"))) -> 40–59 | N3: =VLOOKUP(C3,Customer_Dim!$A$2:$H$501,4,0) -> Male | O3: =VLOOKUP(C3,Customer_Dim!$A$2:$H$501,6,0) -> North Carolina | P3: =VLOOKUP(D3,Product_Dim!$A$1:$G$101,7,0) -> 190
A4: SALE388 | B4: 45780 | C4: CUST1000 | D4: PROD63 | E4: =VLOOKUP(D4,Product_Dim!$A$1:$G$101,2,0) -> Organic Sunscreen Lotion | F4: STORE16 | G4: 1 | H4: 664.71 | I4: 0.1 | J4: PayPal | K4: 598.239 | L4: =VLOOKUP(C4,Customer_Dim!$A$2:$H$501,3,0) -> 55 | M4: =IF(L4<20,"Below 20", IF(L4<40,"20–39", IF(L4<60,"40–59","60+"))) -> 40–59 | N4: =VLOOKUP(C4,Customer_Dim!$A$2:$H$501,4,0) -> Male | O4: =VLOOKUP(C4,Customer_Dim!$A$2:$H$501,6,0) -> North Carolina | P4: =VLOOKUP(D4,Product_Dim!$A$1:$G$101,7,0) -> 458
A5: SALE693 | B5: 45520 | C5: CUST1001 | D5: PROD48 | E5: =VLOOKUP(D5,Product_Dim!$A$1:$G$101,2,0) -> Car Dashboard Phone Holder | F5: STORE2 | G5: 1 | H5: 301.24 | I5: 0.11 | J5: PayPal | K5: 268.1036 | L5: =VLOOKUP(C5,Customer_Dim!$A$2:$H$501,3,0) -> 26 | M5: =IF(L5<20,"Below 20", IF(L5<40,"20–39", IF(L5<60,"40–59","60+"))) -> 20–39 | N5: =VLOOKUP(C5,Customer_Dim!$A$2:$H$501,4,0) -> Female | O5: =VLOOKUP(C5,Customer_Dim!$A$2:$H$501,6,0) -> North Dakota | P5: =VLOOKUP(D5,Product_Dim!$A$1:$G$101,7,0) -> 103
A6: SALE430 | B6: 45445 | C6: CUST1001 | D6: PROD51 | E6: =VLOOKUP(D6,Product_Dim!$A$1:$G$101,2,0) -> HDMI Cable – 2m | F6: STORE14 | G6: 3 | H6: 287.71 | I6: 0.03 | J6: COD | K6: 837.2361 | L6: =VLOOKUP(C6,Customer_Dim!$A$2:$H$501,3,0) -> 26 | M6: =IF(L6<20,"Below 20", IF(L6<40,"20–39", IF(L6<60,"40–59","60+"))) -> 20–39 | N6: =VLOOKUP(C6,Customer_Dim!$A$2:$H$501,4,0) -> Female | O6: =VLOOKUP(C6,Customer_Dim!$A$2:$H$501,6,0) -> North Dakota | P6: =VLOOKUP(D6,Product_Dim!$A$1:$G$101,7,0) -> 246
A7: SALE762 | B7: 45360 | C7: CUST1001 | D7: PROD67 | E7: =VLOOKUP(D7,Product_Dim!$A$1:$G$101,2,0) -> Smart LED Light Strip | F7: STORE0 | G7: 1 | H7: 928.72 | I7: 0.1 | J7: COD | K7: 835.848 | L7: =VLOOKUP(C7,Customer_Dim!$A$2:$H$501,3,0) -> 26 | M7: =IF(L7<20,"Below 20", IF(L7<40,"20–39", IF(L7<60,"40–59","60+"))) -> 20–39 | N7: =VLOOKUP(C7,Customer_Dim!$A$2:$H$501,4,0) -> Female | O7: =VLOOKUP(C7,Customer_Dim!$A$2:$H$501,6,0) -> North Dakota | P7: =VLOOKUP(D7,Product_Dim!$A$1:$G$101,7,0) -> 476
A8: SALE689 | B8: 45876 | C8: CUST1002 | D8: PROD54 | E8: =VLOOKUP(D8,Product_Dim!$A$1:$G$101,2,0) -> Sports Stopwatch Pro | F8: STORE5 | G8: 1 | H8: 692.75 | I8: 0.11 | J8: COD | K8: 616.5475 | L8: =VLOOKUP(C8,Customer_Dim!$A$2:$H$501,3,0) -> 29 | M8: =IF(L8<20,"Below 20", IF(L8<40,"20–39", IF(L8<60,"40–59","60+"))) -> 20–39 | N8: =VLOOKUP(C8,Customer_Dim!$A$2:$H$501,4,0) -> Female | O8: =VLOOKUP(C8,Customer_Dim!$A$2:$H$501,6,0) -> Alabama | P8: =VLOOKUP(D8,Product_Dim!$A$1:$G$101,7,0) -> 185
A9: SALE1040 | B9: 45861 | C9: CUST1002 | D9: PROD75 | E9: =VLOOKUP(D9,Product_Dim!$A$1:$G$101,2,0) -> Women's Ankle Boots | F9: STORE17 | G9: 3 | H9: 202.07 | I9: 0.23 | J9: PayPal | K9: 466.7817 | L9: =VLOOKUP(C9,Customer_Dim!$A$2:$H$501,3,0) -> 29 | M9: =IF(L9<20,"Below 20", IF(L9<40,"20–39", IF(L9<60,"40–59","60+"))) -> 20–39 | N9: =VLOOKUP(C9,Customer_Dim!$A$2:$H$501,4,0) -> Female | O9: =VLOOKUP(C9,Customer_Dim!$A$2:$H$501,6,0) -> Alabama | P9: =VLOOKUP(D9,Product_Dim!$A$1:$G$101,7,0) -> 82
A10: SALE105 | B10: 45214 | C10: CUST1002 | D10: PROD79 | E10: =VLOOKUP(D10,Product_Dim!$A$1:$G$101,2,0) -> Decorative Lamp Shade | F10: STORE17 | G10: 2 | H10: 418.23 | I10: 0.28 | J10: Credit Card | K10: 602.2512 | L10: =VLOOKUP(C10,Customer_Dim!$A$2:$H$501,3,0) -> 29 | M10: =IF(L10<20,"Below 20", IF(L10<40,"20–39", IF(L10<60,"40–59","60+"))) -> 20–39 | N10: =VLOOKUP(C10,Customer_Dim!$A$2:$H$501,4,0) -> Female | O10: =VLOOKUP(C10,Customer_Dim!$A$2:$H$501,6,0) -> Alabama | P10: =VLOOKUP(D10,Product_Dim!$A$1:$G$101,7,0) -> 469
A11: SALE741 | B11: 45372 | C11: CUST1002 | D11: PROD86 | E11: =VLOOKUP(D11,Product_Dim!$A$1:$G$101,2,0) -> Kitchen Cutting Board | F11: STORE9 | G11: 1 | H11: 431.69 | I11: 0.09 | J11: Credit Card | K11: 392.8379 | L11: =VLOOKUP(C11,Customer_Dim!$A$2:$H$501,3,0) -> 29 | M11: =IF(L11<20,"Below 20", IF(L11<40,"20–39", IF(L11<60,"40–59","60+"))) -> 20–39 | N11: =VLOOKUP(C11,Customer_Dim!$A$2:$H$501,4,0) -> Female | O11: =VLOOKUP(C11,Customer_Dim!$A$2:$H$501,6,0) -> Alabama | P11: =VLOOKUP(D11,Product_Dim!$A$1:$G$101,7,0) -> 82
A12: SALE1277 | B12: 45524 | C12: CUST1003 | D12: PROD0 | E12: =VLOOKUP(D12,Product_Dim!$A$1:$G$101,2,0) -> Brother Laser Printer | F12: STORE14 | G12: 1 | H12: 449.6 | I12: 0.01 | J12: PayPal | K12: 445.104 | L12: =VLOOKUP(C12,Customer_Dim!$A$2:$H$501,3,0) -> 59 | M12: =IF(L12<20,"Below 20", IF(L12<40,"20–39", IF(L12<60,"40–59","60+"))) -> 40–59 | N12: =VLOOKUP(C12,Customer_Dim!$A$2:$H$501,4,0) -> Female | O12: =VLOOKUP(C12,Customer_Dim!$A$2:$H$501,6,0) -> Ohio | P12: =VLOOKUP(D12,Product_Dim!$A$1:$G$101,7,0) -> 416
A13: SALE1733 | B13: 45862 | C13: CUST1003 | D13: PROD12 | E13: =VLOOKUP(D13,Product_Dim!$A$1:$G$101,2,0) -> Hair Strengthening Shampoo | F13: STORE9 | G13: 1 | H13: 437.65 | I13: 0.02 | J13: PayPal | K13: 428.897 | L13: =VLOOKUP(C13,Customer_Dim!$A$2:$H$501,3,0) -> 59 | M13: =IF(L13<20,"Below 20", IF(L13<40,"20–39", IF(L13<60,"40–59","60+"))) -> 40–59 | N13: =VLOOKUP(C13,Customer_Dim!$A$2:$H$501,4,0) -> Female | O13: =VLOOKUP(C13,Customer_Dim!$A$2:$H$501,6,0) -> Ohio | P13: =VLOOKUP(D13,Product_Dim!$A$1:$G$101,7,0) -> 460
... A655: SALE1867 | B655: 45602 | C655: CUST1148 | D655: PROD64 | E655: =VLOOKUP(D655,Product_Dim!$A$1:$G$101,2,0) -> Matte Lipstick Set | F655: STORE2 | G655: 4 | H655: 838.99 | I655: 0.16 | J655: Credit Card | K655: 2819.0064 | L655: =VLOOKUP(C655,Customer_Dim!$A$2:$H$501,3,0) -> 42 | M655: =IF(L655<20,"Below 20", IF(L655<40,"20–39", IF(L655<60,"40–59","60+"))) -> 40–59 | N655: =VLOOKUP(C655,Customer_Dim!$A$2:$H$501,4,0) -> Female | O655: =VLOOKUP(C655,Customer_Dim!$A$2:$H$501,6,0) -> Wisconsin | P655: =VLOOKUP(D655,Product_Dim!$A$1:$G$101,7,0) -> 118
A656: SALE52 | B656: 45894 | C656: CUST1148 | D656: PROD89 | E656: =VLOOKUP(D656,Product_Dim!$A$1:$G$101,2,0) -> Face Foundation Kit | F656: STORE6 | G656: 3 | J656: Credit Card | K656: 486.0633 | L656: =VLOOKUP(C656,Customer_Dim!$A$2:$H$501,3,0) -> 42 | M656: =IF(L656<20,"Below 20", IF(L656<40,"20–39", IF(L656<60,"40–59","60+"))) -> 40–59 | N656: =VLOOKUP(C656,Customer_Dim!$A$2:$H$501,4,0) -> Female | O656: =VLOOKUP(C656,Customer_Dim!$A$2:$H$501,6,0) -> Wisconsin | P656: =VLOOKUP(D656,Product_Dim!$A$1:$G$101,7,0) -> 457
A657: SALE1843 | B657: 45379 | C657: CUST1149 | D657: PROD0 | E657: =VLOOKUP(D657,Product_Dim!$A$1:$G$101,2,0) -> Brother Laser Printer | F657: STORE3 | G657: 1 | H657: 140.24 | I657: 0.27 | J657: Credit Card | K657: 102.3752 | L657: =VLOOKUP(C657,Customer_Dim!$A$2:$H$501,3,0) -> 33 | M657: =IF(L657<20,"Below 20", IF(L657<40,"20–39", IF(L657<60,"40–59","60+"))) -> 20–39 | N657: =VLOOKUP(C657,Customer_Dim!$A$2:$H$501,4,0) -> Male | O657: =VLOOKUP(C657,Customer_Dim!$A$2:$H$501,6,0) -> Florida | P657: =VLOOKUP(D657,Product_Dim!$A$1:$G$101,7,0) -> 416
A658: SALE651 | B658: 45721 | C658: CUST1149 | D658: PROD71 | E658: =VLOOKUP(D658,Product_Dim!$A$1:$G$101,2,0) -> Hair Repair Oil Treatment | F658: STORE1 | G658: 1 | H658: 888.05 | I658: 0.2 | J658: PayPal | K658: 710.44 | L658: =VLOOKUP(C658,Customer_Dim!$A$2:$H$501,3,0) -> 33 | M658: =IF(L658<20,"Below 20", IF(L658<40,"20–39", IF(L658<60,"40–59","60+"))) -> 20–39 | N658: =VLOOKUP(C658,Customer_Dim!$A$2:$H$501,4,0) -> Male | O658: =VLOOKUP(C658,Customer_Dim!$A$2:$H$501,6,0) -> Florida | P658: =VLOOKUP(D658,Product_Dim!$A$1:$G$101,7,0) -> 383
A659: SALE643 | B659: 45586 | C659: CUST1149 | D659: PROD76 | E659: =VLOOKUP(D659,Product_Dim!$A$1:$G$101,2,0) -> Wireless Mouse | F659: STORE6 | G659: 3 | H659: 89.78 | I659: 0.2 | J659: COD | K659: 215.472 | L659: =VLOOKUP(C659,Customer_Dim!$A$2:$H$501,3,0) -> 33 | M659: =IF(L659<20,"Below 20", IF(L659<40,"20–39", IF(L659<60,"40–59","60+"))) -> 20–39 | N659: =VLOOKUP(C659,Customer_Dim!$A$2:$H$501,4,0) -> Male | O659: =VLOOKUP(C659,Customer_Dim!$A$2:$H$501,6,0) -> Florida | P659: =VLOOKUP(D659,Product_Dim!$A$1:$G$101,7,0) -> 320
A660: SALE565 | B660: 45843 | C660: CUST1149 | D660: PROD90 | E660: =VLOOKUP(D660,Product_Dim!$A$1:$G$101,2,0) -> Gaming Mouse Pad XL | F660: STORE12 | G660: 1 | H660: 780.16 | I660: 0.02 | J660: COD | K660: 764.5568 | L660: =VLOOKUP(C660,Customer_Dim!$A$2:$H$501,3,0) -> 33 | M660: =IF(L660<20,"Below 20", IF(L660<40,"20–39", IF(L660<60,"40–59","60+"))) -> 20–39 | N660: =VLOOKUP(C660,Customer_Dim!$A$2:$H$501,4,0) -> Male | O660: =VLOOKUP(C660,Customer_Dim!$A$2:$H$501,6,0) -> Florida | P660: =VLOOKUP(D660,Product_Dim!$A$1:$G$101,7,0) -> 361
A661: SALE341 | B661: 45727 | C661: CUST1150 | D661: PROD11 | E661: =VLOOKUP(D661,Product_Dim!$A$1:$G$101,2,0) -> HD Smart TV Stick | F661: STORE15 | G661: 3 | H661: 121.64 | I661: 0.07 | J661: PayPal | K661: 339.3756 | L661: =VLOOKUP(C661,Customer_Dim!$A$2:$H$501,3,0) -> 24 | M661: =IF(L661<20,"Below 20", IF(L661<40,"20–39", IF(L661<60,"40–59","60+"))) -> 20–39 | N661: =VLOOKUP(C661,Customer_Dim!$A$2:$H$501,4,0) -> Male | O661: =VLOOKUP(C661,Customer_Dim!$A$2:$H$501,6,0) -> Mississippi | P661: =VLOOKUP(D661,Product_Dim!$A$1:$G$101,7,0) -> 0
A662: SALE705 | B662: 45803 | C662: CUST1151 | D662: PROD24 | E662: =VLOOKUP(D662,Product_Dim!$A$1:$G$101,2,0) -> Foldable Camping Chair | F662: STORE18 | G662: 4 | H662: 757.9 | I662: 0.22 | J662: PayPal | K662: 2364.648 | L662: =VLOOKUP(C662,Customer_Dim!$A$2:$H$501,3,0) -> 25 | M662: =IF(L662<20,"Below 20", IF(L662<40,"20–39", IF(L662<60,"40–59","60+"))) -> 20–39 | N662: =VLOOKUP(C662,Customer_Dim!$A$2:$H$501,4,0) -> Female | O662: =VLOOKUP(C662,Customer_Dim!$A$2:$H$501,6,0) -> Oregon | P662: =VLOOKUP(D662,Product_Dim!$A$1:$G$101,7,0) -> 340
A663: SALE1070 | B663: 45576 | C663: CUST1151 | D663: PROD50 | E663: =VLOOKUP(D663,Product_Dim!$A$1:$G$101,2,0) -> Boxing Hand Wraps | F663: STORE2 | G663: 4 | H663: 694.61 | I663: 0.18 | J663: COD | K663: 2278.3208 | L663: =VLOOKUP(C663,Customer_Dim!$A$2:$H$501,3,0) -> 25 | M663: =IF(L663<20,"Below 20", IF(L663<40,"20–39", IF(L663<60,"40–59","60+"))) -> 20–39 | N663: =VLOOKUP(C663,Customer_Dim!$A$2:$H$501,4,0) -> Female | O663: =VLOOKUP(C663,Customer_Dim!$A$2:$H$501,6,0) -> Oregon | P663: =VLOOKUP(D663,Product_Dim!$A$1:$G$101,7,0) -> 260
A664: SALE1112 | B664: 45316 | C664: CUST1151 | D664: PROD73 | E664: =VLOOKUP(D664,Product_Dim!$A$1:$G$101,2,0) -> Shin Guards – Adult | F664: STORE5 | G664: 2 | H664: 644 | I664: 0.04 | J664: PayPal | K664: 1236.48 | L664: =VLOOKUP(C664,Customer_Dim!$A$2:$H$501,3,0) -> 25 | M664: =IF(L664<20,"Below 20", IF(L664<40,"20–39", IF(L664<60,"40–59","60+"))) -> 20–39 | N664: =VLOOKUP(C664,Customer_Dim!$A$2:$H$501,4,0) -> Female | O664: =VLOOKUP(C664,Customer_Dim!$A$2:$H$501,6,0) -> Oregon | P664: =VLOOKUP(D664,Product_Dim!$A$1:$G$101,7,0) -> 359
A665: SALE1664 | B665: 45798 | C665: CUST1152 | D665: PROD39 | E665: =VLOOKUP(D665,Product_Dim!$A$1:$G$101,2,0) -> Portable Power Bank | F665: STORE14 | G665: 3 | H665: 343.97 | I665: 0.04 | J665: COD | K665: 990.6336 | L665: =VLOOKUP(C665,Customer_Dim!$A$2:$H$501,3,0) -> 41 | M665: =IF(L665<20,"Below 20", IF(L665<40,"20–39", IF(L665<60,"40–59","60+"))) -> 40–59 | N665: =VLOOKUP(C665,Customer_Dim!$A$2:$H$501,4,0) -> Female | O665: =VLOOKUP(C665,Customer_Dim!$A$2:$H$501,6,0) -> Missouri | P665: =VLOOKUP(D665,Product_Dim!$A$1:$G$101,7,0) -> 301
A666: SALE1420 | B666: 45875 | C666: CUST1152 | D666: PROD53 | E666: =VLOOKUP(D666,Product_Dim!$A$1:$G$101,2,0) -> Men's Track Pants | F666: STORE19 | G666: 2 | H666: 664.5 | I666: 0.23 | J666: Credit Card | K666: 1023.33 | L666: =VLOOKUP(C666,Customer_Dim!$A$2:$H$501,3,0) -> 41 | M666: =IF(L666<20,"Below 20", IF(L666<40,"20–39", IF(L666<60,"40–59","60+"))) -> 40–59 | N666: =VLOOKUP(C666,Customer_Dim!$A$2:$H$501,4,0) -> Female | O666: =VLOOKUP(C666,Customer_Dim!$A$2:$H$501,6,0) -> Missouri | P666: =VLOOKUP(D666,Product_Dim!$A$1:$G$101,7,0) -> 125
A667: SALE7 | B667: 45248 | C667: CUST1152 | D667: PROD70 | E667: =VLOOKUP(D667,Product_Dim!$A$1:$G$101,2,0) -> Kitchen Storage Rack | F667: STORE8 | G667: 4 | H667: 342.39 | I667: 0.23 | J667: PayPal | K667: 1054.5612 | L667: =VLOOKUP(C667,Customer_Dim!$A$2:$H$501,3,0) -> 41 | M667: =IF(L667<20,"Below 20", IF(L667<40,"20–39", IF(L667<60,"40–59","60+"))) -> 40–59 | N667: =VLOOKUP(C667,Customer_Dim!$A$2:$H$501,4,0) -> Female | O667: =VLOOKUP(C667,Customer_Dim!$A$2:$H$501,6,0) -> Missouri | P667: =VLOOKUP(D667,Product_Dim!$A$1:$G$101,7,0) -> 89
A668: SALE114 | B668: 45482 | C668: CUST1152 | D668: PROD91 | E668: =VLOOKUP(D668,Product_Dim!$A$1:$G$101,2,0) -> Women's High Heels | F668: STORE4 | G668: 2 | H668: 731.01 | I668: 0.05 | J668: PayPal | K668: 1388.919 | L668: =VLOOKUP(C668,Customer_Dim!$A$2:$H$501,3,0) -> 41 | M668: =IF(L668<20,"Below 20", IF(L668<40,"20–39", IF(L668<60,"40–59","60+"))) -> 40–59 | N668: =VLOOKUP(C668,Customer_Dim!$A$2:$H$501,4,0) -> Female | O668: =VLOOKUP(C668,Customer_Dim!$A$2:$H$501,6,0) -> Missouri | P668: =VLOOKUP(D668,Product_Dim!$A$1:$G$101,7,0) -> 496
... A922: SALE839 | B922: 45755 | C922: CUST1213 | D922: PROD87 | E922: =VLOOKUP(D922,Product_Dim!$A$1:$G$101,2,0) -> LED Bedside Lamp | F922: STORE0 | G922: 3 | H922: 693.42 | I922: 0.08 | J922: PayPal | K922: 1913.8392 | L922: =VLOOKUP(C922,Customer_Dim!$A$2:$H$501,3,0) -> 42 | M922: =IF(L922<20,"Below 20", IF(L922<40,"20–39", IF(L922<60,"40–59","60+"))) -> 40–59 | N922: =VLOOKUP(C922,Customer_Dim!$A$2:$H$501,4,0) -> Female | O922: =VLOOKUP(C922,Customer_Dim!$A$2:$H$501,6,0) -> North Dakota | P922: =VLOOKUP(D922,Product_Dim!$A$1:$G$101,7,0) -> 220
A923: SALE26 | B923: 45294 | C923: CUST1213 | D923: PROD98 | E923: =VLOOKUP(D923,Product_Dim!$A$1:$G$101,2,0) -> Portable Bluetooth Speaker | F923: STORE8 | G923: 4 | H923: 156.16 | J923: Credit Card | K923: 599.6544 | L923: =VLOOKUP(C923,Customer_Dim!$A$2:$H$501,3,0) -> 42 | M923: =IF(L923<20,"Below 20", IF(L923<40,"20–39", IF(L923<60,"40–59","60+"))) -> 40–59 | N923: =VLOOKUP(C923,Customer_Dim!$A$2:$H$501,4,0) -> Female | O923: =VLOOKUP(C923,Customer_Dim!$A$2:$H$501,6,0) -> North Dakota | P923: =VLOOKUP(D923,Product_Dim!$A$1:$G$101,7,0) -> 73
A924: SALE351 | B924: 45621 | C924: CUST1214 | D924: PROD12 | E924: =VLOOKUP(D924,Product_Dim!$A$1:$G$101,2,0) -> Hair Strengthening Shampoo | F924: STORE18 | G924: 3 | H924: 877.71 | I924: 0.12 | J924: PayPal | K924: 2317.1544 | L924: =VLOOKUP(C924,Customer_Dim!$A$2:$H$501,3,0) -> 61 | M924: =IF(L924<20,"Below 20", IF(L924<40,"20–39", IF(L924<60,"40–59","60+"))) -> 60+ | N924: =VLOOKUP(C924,Customer_Dim!$A$2:$H$501,4,0) -> Male | O924: =VLOOKUP(C924,Customer_Dim!$A$2:$H$501,6,0) -> Montana | P924: =VLOOKUP(D924,Product_Dim!$A$1:$G$101,7,0) -> 460
A925: SALE588 | B925: 45357 | C925: CUST1214 | D925: PROD71 | E925: =VLOOKUP(D925,Product_Dim!$A$1:$G$101,2,0) -> Hair Repair Oil Treatment | F925: STORE18 | G925: 1 | H925: 250.95 | I925: 0.03 | J925: PayPal | K925: 243.4215 | L925: =VLOOKUP(C925,Customer_Dim!$A$2:$H$501,3,0) -> 61 | M925: =IF(L925<20,"Below 20", IF(L925<40,"20–39", IF(L925<60,"40–59","60+"))) -> 60+ | N925: =VLOOKUP(C925,Customer_Dim!$A$2:$H$501,4,0) -> Male | O925: =VLOOKUP(C925,Customer_Dim!$A$2:$H$501,6,0) -> Montana | P925: =VLOOKUP(D925,Product_Dim!$A$1:$G$101,7,0) -> 383
A926: SALE1792 | B926: 45387 | C926: CUST1214 | D926: PROD73 | E926: =VLOOKUP(D926,Product_Dim!$A$1:$G$101,2,0) -> Shin Guards – Adult | F926: STORE14 | G926: 2 | H926: 720.15 | I926: 0.22 | J926: COD | K926: 1123.434 | L926: =VLOOKUP(C926,Customer_Dim!$A$2:$H$501,3,0) -> 61 | M926: =IF(L926<20,"Below 20", IF(L926<40,"20–39", IF(L926<60,"40–59","60+"))) -> 60+ | N926: =VLOOKUP(C926,Customer_Dim!$A$2:$H$501,4,0) -> Male | O926: =VLOOKUP(C926,Customer_Dim!$A$2:$H$501,6,0) -> Montana | P926: =VLOOKUP(D926,Product_Dim!$A$1:$G$101,7,0) -> 359
A927: SALE109 | B927: 45738 | C927: CUST1214 | D927: PROD91 | E927: =VLOOKUP(D927,Product_Dim!$A$1:$G$101,2,0) -> Women's High Heels | F927: STORE0 | G927: 3 | H927: 376.46 | I927: 0.09 | J927: COD | K927: 1027.7358 | L927: =VLOOKUP(C927,Customer_Dim!$A$2:$H$501,3,0) -> 61 | M927: =IF(L927<20,"Below 20", IF(L927<40,"20–39", IF(L927<60,"40–59","60+"))) -> 60+ | N927: =VLOOKUP(C927,Customer_Dim!$A$2:$H$501,4,0) -> Male | O927: =VLOOKUP(C927,Customer_Dim!$A$2:$H$501,6,0) -> Montana | P927: =VLOOKUP(D927,Product_Dim!$A$1:$G$101,7,0) -> 496
A928: SALE456 | B928: 45527 | C928: CUST1215 | D928: PROD32 | E928: =VLOOKUP(D928,Product_Dim!$A$1:$G$101,2,0) -> Vitamin C Face Serum | F928: STORE9 | G928: 4 | H928: 315.95 | I928: 0.19 | J928: COD | K928: 1023.678 | L928: =VLOOKUP(C928,Customer_Dim!$A$2:$H$501,3,0) -> 50 | M928: =IF(L928<20,"Below 20", IF(L928<40,"20–39", IF(L928<60,"40–59","60+"))) -> 40–59 | N928: =VLOOKUP(C928,Customer_Dim!$A$2:$H$501,4,0) -> Female | O928: =VLOOKUP(C928,Customer_Dim!$A$2:$H$501,6,0) -> Oregon | P928: =VLOOKUP(D928,Product_Dim!$A$1:$G$101,7,0) -> 244
A929: SALE926 | B929: 45369 | C929: CUST1215 | D929: PROD67 | E929: =VLOOKUP(D929,Product_Dim!$A$1:$G$101,2,0) -> Smart LED Light Strip | F929: STORE19 | G929: 3 | H929: 968.88 | I929: 0.15 | J929: Credit Card | K929: 2470.644 | L929: =VLOOKUP(C929,Customer_Dim!$A$2:$H$501,3,0) -> 50 | M929: =IF(L929<20,"Below 20", IF(L929<40,"20–39", IF(L929<60,"40–59","60+"))) -> 40–59 | N929: =VLOOKUP(C929,Customer_Dim!$A$2:$H$501,4,0) -> Female | O929: =VLOOKUP(C929,Customer_Dim!$A$2:$H$501,6,0) -> Oregon | P929: =VLOOKUP(D929,Product_Dim!$A$1:$G$101,7,0) -> 476
A930: SALE299 | B930: 45348 | C930: CUST1216 | D930: PROD22 | E930: =VLOOKUP(D930,Product_Dim!$A$1:$G$101,2,0) -> Carbon Fiber Tennis Racket | F930: STORE19 | G930: 2 | H930: 873.1 | I930: 0.12 | J930: PayPal | K930: 1536.656 | L930: =VLOOKUP(C930,Customer_Dim!$A$2:$H$501,3,0) -> 44 | M930: =IF(L930<20,"Below 20", IF(L930<40,"20–39", IF(L930<60,"40–59","60+"))) -> 40–59 | N930: =VLOOKUP(C930,Customer_Dim!$A$2:$H$501,4,0) -> Male | O930: =VLOOKUP(C930,Customer_Dim!$A$2:$H$501,6,0) -> California | P930: =VLOOKUP(D930,Product_Dim!$A$1:$G$101,7,0) -> 432
A931: SALE364 | B931: 45723 | C931: CUST1216 | D931: PROD35 | E931: =VLOOKUP(D931,Product_Dim!$A$1:$G$101,2,0) -> Bedroom Table Lamp | F931: STORE18 | G931: 1 | H931: 213.69 | I931: 0.28 | J931: COD | K931: 153.8568 | L931: =VLOOKUP(C931,Customer_Dim!$A$2:$H$501,3,0) -> 44 | M931: =IF(L931<20,"Below 20", IF(L931<40,"20–39", IF(L931<60,"40–59","60+"))) -> 40–59 | N931: =VLOOKUP(C931,Customer_Dim!$A$2:$H$501,4,0) -> Male | O931: =VLOOKUP(C931,Customer_Dim!$A$2:$H$501,6,0) -> California | P931: =VLOOKUP(D931,Product_Dim!$A$1:$G$101,7,0) -> 329
A932: SALE605 | B932: 45222 | C932: CUST1216 | D932: PROD72 | E932: =VLOOKUP(D932,Product_Dim!$A$1:$G$101,2,0) -> Professional Jump Rope | F932: STORE0 | G932: 1 | H932: 61.11 | I932: 0.1 | J932: PayPal | K932: 54.999 | L932: =VLOOKUP(C932,Customer_Dim!$A$2:$H$501,3,0) -> 44 | M932: =IF(L932<20,"Below 20", IF(L932<40,"20–39", IF(L932<60,"40–59","60+"))) -> 40–59 | N932: =VLOOKUP(C932,Customer_Dim!$A$2:$H$501,4,0) -> Male | O932: =VLOOKUP(C932,Customer_Dim!$A$2:$H$501,6,0) -> California | P932: =VLOOKUP(D932,Product_Dim!$A$1:$G$101,7,0) -> 300
A933: SALE239 | B933: 45861 | C933: CUST1216 | D933: PROD86 | E933: =VLOOKUP(D933,Product_Dim!$A$1:$G$101,2,0) -> Kitchen Cutting Board | F933: STORE8 | G933: 3 | H933: 91.7 | I933: 0.08 | J933: COD | K933: 253.092 | L933: =VLOOKUP(C933,Customer_Dim!$A$2:$H$501,3,0) -> 44 | M933: =IF(L933<20,"Below 20", IF(L933<40,"20–39", IF(L933<60,"40–59","60+"))) -> 40–59 | N933: =VLOOKUP(C933,Customer_Dim!$A$2:$H$501,4,0) -> Male | O933: =VLOOKUP(C933,Customer_Dim!$A$2:$H$501,6,0) -> California | P933: =VLOOKUP(D933,Product_Dim!$A$1:$G$101,7,0) -> 82
A934: SALE1702 | B934: 45268 | C934: CUST1217 | D934: PROD37 | E934: =VLOOKUP(D934,Product_Dim!$A$1:$G$101,2,0) -> Men's Casual Sneakers | F934: STORE7 | G934: 2 | H934: 985.79 | I934: 0.04 | J934: PayPal | K934: 1892.7168 | L934: =VLOOKUP(C934,Customer_Dim!$A$2:$H$501,3,0) -> 42 | M934: =IF(L934<20,"Below 20", IF(L934<40,"20–39", IF(L934<60,"40–59","60+"))) -> 40–59 | N934: =VLOOKUP(C934,Customer_Dim!$A$2:$H$501,4,0) -> Male | O934: =VLOOKUP(C934,Customer_Dim!$A$2:$H$501,6,0) -> Missouri | P934: =VLOOKUP(D934,Product_Dim!$A$1:$G$101,7,0) -> 214
...

Sheet Age group - Gender - Sales
A1: Row Labels | B1: Sum of Total_Amount | E1: Row Labels | F1: Sum of Total_Amount
A2: 20–39 | B2: 876431.3 | E2: Female | F2: 1231444.2
A3: 40–59 | B3: 975956.55 | E3: Male | F3: 942950.47
A4: 60+ | B4: 242004.56 | E4: Grand Total | F4: 2174394.7
A5: Below 20 | B5: 80002.295
A6: Grand Total | B6: 2174394.7

Sheet Year - Sales
A1: Row Labels | B1: Sum of Total_Amount
A2: 2023 | B2: 223812.72
A3: 2024 | B3: 1093911.8
A4: 2025 | B4: 856670.18
A5: Grand Total | B5: 2174394.7

Sheet Product Sales Dashboard
A1: PRODUCT SALES DASHBOARD

